2024-10-06 18:05:32,914 - ERROR - Uncaught exception
Traceback (most recent call last):
  File "/home/frigiel/Documents/VSCODE/Kaboom/Server/server.py", line 44, in <module>
    accept()
  File "/home/frigiel/Documents/VSCODE/Kaboom/Server/server.py", line 29, in accept
    conn, address = server_socket.accept()
                    ^^^^^^^^^^^^^^^^^^^^^^
  File "/usr/lib/python3.12/socket.py", line 295, in accept
    fd, addr = self._accept()
               ^^^^^^^^^^^^^^
KeyboardInterrupt
2024-10-06 18:05:33,350 - ERROR - Exception ignored in: 
2024-10-06 18:05:33,351 - ERROR - <module 'threading' from '/usr/lib/python3.12/threading.py'>
2024-10-06 18:05:33,351 - ERROR - 

2024-10-06 18:05:33,351 - ERROR - Traceback (most recent call last):

2024-10-06 18:05:33,351 - ERROR -   File "/usr/lib/python3.12/threading.py", line 1624, in _shutdown

2024-10-06 18:05:33,351 - ERROR -     
2024-10-06 18:05:33,351 - ERROR - lock.acquire()
2024-10-06 18:05:33,351 - ERROR - 

2024-10-06 18:05:33,351 - ERROR - KeyboardInterrupt
2024-10-06 18:05:33,351 - ERROR - : 
2024-10-06 18:05:33,351 - ERROR - 
2024-10-06 18:05:33,351 - ERROR - 

2024-10-06 18:08:58,925 - ERROR - Uncaught exception
Traceback (most recent call last):
  File "/home/frigiel/Documents/VSCODE/Kaboom/Server/server.py", line 44, in <module>
    accept()
  File "/home/frigiel/Documents/VSCODE/Kaboom/Server/server.py", line 29, in accept
    conn, address = server_socket.accept()
                    ^^^^^^^^^^^^^^^^^^^^^^
  File "/usr/lib/python3.12/socket.py", line 295, in accept
    fd, addr = self._accept()
               ^^^^^^^^^^^^^^
KeyboardInterrupt
2024-10-06 18:08:59,150 - ERROR - Exception ignored in: 
2024-10-06 18:08:59,151 - ERROR - <module 'threading' from '/usr/lib/python3.12/threading.py'>
2024-10-06 18:08:59,151 - ERROR - 

2024-10-06 18:08:59,151 - ERROR - Traceback (most recent call last):

2024-10-06 18:08:59,151 - ERROR -   File "/usr/lib/python3.12/threading.py", line 1624, in _shutdown

2024-10-06 18:08:59,151 - ERROR -     
2024-10-06 18:08:59,151 - ERROR - lock.acquire()
2024-10-06 18:08:59,151 - ERROR - 

2024-10-06 18:08:59,151 - ERROR - KeyboardInterrupt
2024-10-06 18:08:59,151 - ERROR - : 
2024-10-06 18:08:59,151 - ERROR - 
2024-10-06 18:08:59,151 - ERROR - 

2024-10-06 18:10:42,005 - ERROR - Uncaught exception
Traceback (most recent call last):
  File "/home/frigiel/Documents/VSCODE/Kaboom/Server/server.py", line 44, in <module>
    accept()
  File "/home/frigiel/Documents/VSCODE/Kaboom/Server/server.py", line 29, in accept
    conn, address = server_socket.accept()
                    ^^^^^^^^^^^^^^^^^^^^^^
  File "/usr/lib/python3.12/socket.py", line 295, in accept
    fd, addr = self._accept()
               ^^^^^^^^^^^^^^
KeyboardInterrupt
2024-10-06 18:10:44,204 - ERROR - Exception ignored in: 
2024-10-06 18:10:44,204 - ERROR - <module 'threading' from '/usr/lib/python3.12/threading.py'>
2024-10-06 18:10:44,204 - ERROR - 

2024-10-06 18:10:44,204 - ERROR - Traceback (most recent call last):

2024-10-06 18:10:44,205 - ERROR -   File "/usr/lib/python3.12/threading.py", line 1624, in _shutdown

2024-10-06 18:10:44,205 - ERROR -     
2024-10-06 18:10:44,205 - ERROR - lock.acquire()
2024-10-06 18:10:44,205 - ERROR - 

2024-10-06 18:10:44,205 - ERROR - KeyboardInterrupt
2024-10-06 18:10:44,206 - ERROR - : 
2024-10-06 18:10:44,206 - ERROR - 
2024-10-06 18:10:44,206 - ERROR - 

2024-10-06 18:12:21,202 - ERROR - Uncaught exception
Traceback (most recent call last):
  File "/home/frigiel/Documents/VSCODE/Kaboom/Server/server.py", line 44, in <module>
    accept()
  File "/home/frigiel/Documents/VSCODE/Kaboom/Server/server.py", line 29, in accept
    conn, address = server_socket.accept()
                    ^^^^^^^^^^^^^^^^^^^^^^
  File "/usr/lib/python3.12/socket.py", line 295, in accept
    fd, addr = self._accept()
               ^^^^^^^^^^^^^^
KeyboardInterrupt
2024-10-06 18:12:21,566 - ERROR - Exception ignored in: 
2024-10-06 18:12:21,566 - ERROR - <module 'threading' from '/usr/lib/python3.12/threading.py'>
2024-10-06 18:12:21,566 - ERROR - 

2024-10-06 18:12:21,567 - ERROR - Traceback (most recent call last):

2024-10-06 18:12:21,567 - ERROR -   File "/usr/lib/python3.12/threading.py", line 1624, in _shutdown

2024-10-06 18:12:21,569 - ERROR -     
2024-10-06 18:12:21,569 - ERROR - lock.acquire()
2024-10-06 18:12:21,569 - ERROR - 

2024-10-06 18:12:21,569 - ERROR - KeyboardInterrupt
2024-10-06 18:12:21,570 - ERROR - : 
2024-10-06 18:12:21,570 - ERROR - 
2024-10-06 18:12:21,570 - ERROR - 

2024-10-06 18:18:04,682 - ERROR - Uncaught exception
Traceback (most recent call last):
  File "/home/frigiel/Documents/VSCODE/Kaboom/Server/server.py", line 44, in <module>
    accept()
  File "/home/frigiel/Documents/VSCODE/Kaboom/Server/server.py", line 29, in accept
    conn, address = server_socket.accept()
                    ^^^^^^^^^^^^^^^^^^^^^^
  File "/usr/lib/python3.12/socket.py", line 295, in accept
    fd, addr = self._accept()
               ^^^^^^^^^^^^^^
KeyboardInterrupt
2024-10-06 18:40:26,659 - ERROR - Exception in thread 
2024-10-06 18:40:26,659 - ERROR - Thread-2
2024-10-06 18:40:26,659 - ERROR - :

2024-10-06 18:40:26,659 - ERROR - 
2024-10-06 18:40:26,659 - ERROR - Traceback (most recent call last):

2024-10-06 18:40:26,659 - ERROR - 
2024-10-06 18:40:26,659 - ERROR -   File "/usr/lib/python3.12/threading.py", line 1075, in _bootstrap_inner

2024-10-06 18:40:26,660 - ERROR - 
2024-10-06 18:40:26,660 - ERROR -     
2024-10-06 18:40:26,660 - ERROR - self.run()
2024-10-06 18:40:26,660 - ERROR - 

2024-10-06 18:40:26,660 - ERROR - 
2024-10-06 18:40:26,660 - ERROR -   File "/home/frigiel/Documents/VSCODE/Kaboom/Server/server_reception.py", line 42, in run

2024-10-06 18:40:26,661 - ERROR - 
2024-10-06 18:40:26,661 - ERROR -     
2024-10-06 18:40:26,661 - ERROR - self.reception(self.conn)
2024-10-06 18:40:26,661 - ERROR - 

2024-10-06 18:40:26,661 - ERROR - 
2024-10-06 18:40:26,661 - ERROR -   File "/home/frigiel/Documents/VSCODE/Kaboom/Server/server_reception.py", line 104, in reception

2024-10-06 18:40:26,661 - ERROR - 
2024-10-06 18:40:26,661 - ERROR -     
2024-10-06 18:40:26,661 - ERROR - self.new_user(conn, message)
2024-10-06 18:40:26,661 - ERROR - 

2024-10-06 18:40:26,661 - ERROR - 
2024-10-06 18:40:26,662 - ERROR -   File "/home/frigiel/Documents/VSCODE/Kaboom/Server/server_reception.py", line 373, in new_user

2024-10-06 18:40:26,662 - ERROR - 
2024-10-06 18:40:26,662 - ERROR -     
2024-10-06 18:40:26,662 - ERROR - self.send_client(conn, "NAME_CORRECT|")
2024-10-06 18:40:26,662 - ERROR - 

2024-10-06 18:40:26,662 - ERROR - 
2024-10-06 18:40:26,662 - ERROR -   File "/home/frigiel/Documents/VSCODE/Kaboom/Server/server_reception.py", line 919, in send_client

2024-10-06 18:40:26,663 - ERROR - 
2024-10-06 18:40:26,663 - ERROR -     
2024-10-06 18:40:26,663 - ERROR - infos_logger.log_infos("[SEND]", f"{message - str(conn)}")
2024-10-06 18:40:26,663 - ERROR - 

2024-10-06 18:40:26,664 - ERROR - 
2024-10-06 18:40:26,664 - ERROR -  
2024-10-06 18:40:26,664 - ERROR -  
2024-10-06 18:40:26,664 - ERROR -  
2024-10-06 18:40:26,664 - ERROR -  
2024-10-06 18:40:26,664 - ERROR -  
2024-10-06 18:40:26,664 - ERROR -  
2024-10-06 18:40:26,664 - ERROR -  
2024-10-06 18:40:26,664 - ERROR -  
2024-10-06 18:40:26,664 - ERROR -  
2024-10-06 18:40:26,664 - ERROR -  
2024-10-06 18:40:26,664 - ERROR -  
2024-10-06 18:40:26,664 - ERROR -  
2024-10-06 18:40:26,664 - ERROR -  
2024-10-06 18:40:26,664 - ERROR -  
2024-10-06 18:40:26,664 - ERROR -  
2024-10-06 18:40:26,664 - ERROR -  
2024-10-06 18:40:26,664 - ERROR -  
2024-10-06 18:40:26,665 - ERROR -  
2024-10-06 18:40:26,665 - ERROR -  
2024-10-06 18:40:26,665 - ERROR -  
2024-10-06 18:40:26,665 - ERROR -  
2024-10-06 18:40:26,665 - ERROR -  
2024-10-06 18:40:26,665 - ERROR -  
2024-10-06 18:40:26,665 - ERROR -  
2024-10-06 18:40:26,665 - ERROR -  
2024-10-06 18:40:26,665 - ERROR -  
2024-10-06 18:40:26,665 - ERROR -  
2024-10-06 18:40:26,665 - ERROR -  
2024-10-06 18:40:26,665 - ERROR -  
2024-10-06 18:40:26,665 - ERROR -  
2024-10-06 18:40:26,665 - ERROR -  
2024-10-06 18:40:26,665 - ERROR -  
2024-10-06 18:40:26,665 - ERROR -  
2024-10-06 18:40:26,666 - ERROR -  
2024-10-06 18:40:26,666 - ERROR -  
2024-10-06 18:40:26,666 - ERROR -  
2024-10-06 18:40:26,666 - ERROR -  
2024-10-06 18:40:26,666 - ERROR -  
2024-10-06 18:40:26,666 - ERROR -  
2024-10-06 18:40:26,666 - ERROR -  
2024-10-06 18:40:26,666 - ERROR - ~
2024-10-06 18:40:26,666 - ERROR - ~
2024-10-06 18:40:26,666 - ERROR - ~
2024-10-06 18:40:26,666 - ERROR - ~
2024-10-06 18:40:26,666 - ERROR - ~
2024-10-06 18:40:26,666 - ERROR - ~
2024-10-06 18:40:26,666 - ERROR - ~
2024-10-06 18:40:26,666 - ERROR - ~
2024-10-06 18:40:26,666 - ERROR - ^
2024-10-06 18:40:26,666 - ERROR - ~
2024-10-06 18:40:26,667 - ERROR - ~
2024-10-06 18:40:26,667 - ERROR - ~
2024-10-06 18:40:26,667 - ERROR - ~
2024-10-06 18:40:26,667 - ERROR - ~
2024-10-06 18:40:26,667 - ERROR - ~
2024-10-06 18:40:26,667 - ERROR - ~
2024-10-06 18:40:26,667 - ERROR - ~
2024-10-06 18:40:26,667 - ERROR - ~
2024-10-06 18:40:26,667 - ERROR - ~
2024-10-06 18:40:26,667 - ERROR - 

2024-10-06 18:40:26,667 - ERROR - 
2024-10-06 18:40:26,667 - ERROR - TypeError
2024-10-06 18:40:26,667 - ERROR - : 
2024-10-06 18:40:26,667 - ERROR - unsupported operand type(s) for -: 'str' and 'str'
2024-10-06 18:40:26,667 - ERROR - 

2024-10-06 18:42:40,493 - ERROR - Uncaught exception
Traceback (most recent call last):
  File "/home/frigiel/Documents/VSCODE/Kaboom/Server/server.py", line 44, in <module>
    accept()
  File "/home/frigiel/Documents/VSCODE/Kaboom/Server/server.py", line 29, in accept
    conn, address = server_socket.accept()
                    ^^^^^^^^^^^^^^^^^^^^^^
  File "/usr/lib/python3.12/socket.py", line 295, in accept
    fd, addr = self._accept()
               ^^^^^^^^^^^^^^
KeyboardInterrupt
2024-10-06 18:42:40,794 - ERROR - Exception ignored in: 
2024-10-06 18:42:40,794 - ERROR - <module 'threading' from '/usr/lib/python3.12/threading.py'>
2024-10-06 18:42:40,794 - ERROR - 

2024-10-06 18:42:40,794 - ERROR - Traceback (most recent call last):

2024-10-06 18:42:40,794 - ERROR -   File "/usr/lib/python3.12/threading.py", line 1624, in _shutdown

2024-10-06 18:42:40,794 - ERROR -     
2024-10-06 18:42:40,795 - ERROR - lock.acquire()
2024-10-06 18:42:40,795 - ERROR - 

2024-10-06 18:42:40,795 - ERROR - KeyboardInterrupt
2024-10-06 18:42:40,795 - ERROR - : 
2024-10-06 18:42:40,795 - ERROR - 
2024-10-06 18:42:40,795 - ERROR - 

2024-10-06 18:53:33,119 - ERROR - Uncaught exception
Traceback (most recent call last):
  File "/home/frigiel/Documents/VSCODE/Kaboom/Server/server.py", line 44, in <module>
    accept()
  File "/home/frigiel/Documents/VSCODE/Kaboom/Server/server.py", line 29, in accept
    conn, address = server_socket.accept()
                    ^^^^^^^^^^^^^^^^^^^^^^
  File "/usr/lib/python3.12/socket.py", line 295, in accept
    fd, addr = self._accept()
               ^^^^^^^^^^^^^^
KeyboardInterrupt
2024-10-06 19:59:08,072 - ERROR - Uncaught exception
Traceback (most recent call last):
  File "/home/frigiel/Documents/VSCODE/Kaboom/Server/server.py", line 44, in <module>
    accept()
  File "/home/frigiel/Documents/VSCODE/Kaboom/Server/server.py", line 29, in accept
    conn, address = server_socket.accept()
                    ^^^^^^^^^^^^^^^^^^^^^^
  File "/usr/lib/python3.12/socket.py", line 295, in accept
    fd, addr = self._accept()
               ^^^^^^^^^^^^^^
KeyboardInterrupt
2024-10-06 19:59:08,797 - ERROR - Exception ignored in: 
2024-10-06 19:59:08,798 - ERROR - <module 'threading' from '/usr/lib/python3.12/threading.py'>
2024-10-06 19:59:08,798 - ERROR - 

2024-10-06 19:59:08,798 - ERROR - Traceback (most recent call last):

2024-10-06 19:59:08,798 - ERROR -   File "/usr/lib/python3.12/threading.py", line 1624, in _shutdown

2024-10-06 19:59:08,804 - ERROR -     
2024-10-06 19:59:08,804 - ERROR - lock.acquire()
2024-10-06 19:59:08,804 - ERROR - 

2024-10-06 19:59:08,805 - ERROR - KeyboardInterrupt
2024-10-06 19:59:08,805 - ERROR - : 
2024-10-06 19:59:08,805 - ERROR - 
2024-10-06 19:59:08,805 - ERROR - 

2024-10-06 20:05:08,615 - ERROR - Uncaught exception
Traceback (most recent call last):
  File "/home/frigiel/Documents/VSCODE/Kaboom/Server/server.py", line 44, in <module>
    accept()
  File "/home/frigiel/Documents/VSCODE/Kaboom/Server/server.py", line 29, in accept
    conn, address = server_socket.accept()
                    ^^^^^^^^^^^^^^^^^^^^^^
  File "/usr/lib/python3.12/socket.py", line 295, in accept
    fd, addr = self._accept()
               ^^^^^^^^^^^^^^
KeyboardInterrupt
2024-10-06 20:05:09,793 - ERROR - Exception ignored in: 
2024-10-06 20:05:09,793 - ERROR - <module 'threading' from '/usr/lib/python3.12/threading.py'>
2024-10-06 20:05:09,793 - ERROR - 

2024-10-06 20:05:09,793 - ERROR - Traceback (most recent call last):

2024-10-06 20:05:09,793 - ERROR -   File "/usr/lib/python3.12/threading.py", line 1624, in _shutdown

2024-10-06 20:05:09,809 - ERROR -     
2024-10-06 20:05:09,809 - ERROR - lock.acquire()
2024-10-06 20:05:09,809 - ERROR - 

2024-10-06 20:05:09,809 - ERROR - KeyboardInterrupt
2024-10-06 20:05:09,809 - ERROR - : 
2024-10-06 20:05:09,809 - ERROR - 
2024-10-06 20:05:09,809 - ERROR - 

2024-10-06 20:05:49,396 - ERROR - Uncaught exception
Traceback (most recent call last):
  File "/home/frigiel/Documents/VSCODE/Kaboom/Server/server.py", line 44, in <module>
    accept()
  File "/home/frigiel/Documents/VSCODE/Kaboom/Server/server.py", line 29, in accept
    conn, address = server_socket.accept()
                    ^^^^^^^^^^^^^^^^^^^^^^
  File "/usr/lib/python3.12/socket.py", line 295, in accept
    fd, addr = self._accept()
               ^^^^^^^^^^^^^^
KeyboardInterrupt
2024-10-06 20:05:49,602 - ERROR - Exception ignored in: 
2024-10-06 20:05:49,602 - ERROR - <module 'threading' from '/usr/lib/python3.12/threading.py'>
2024-10-06 20:05:49,602 - ERROR - 

2024-10-06 20:05:49,603 - ERROR - Traceback (most recent call last):

2024-10-06 20:05:49,603 - ERROR -   File "/usr/lib/python3.12/threading.py", line 1624, in _shutdown

2024-10-06 20:05:49,605 - ERROR -     
2024-10-06 20:05:49,605 - ERROR - lock.acquire()
2024-10-06 20:05:49,605 - ERROR - 

2024-10-06 20:05:49,605 - ERROR - KeyboardInterrupt
2024-10-06 20:05:49,606 - ERROR - : 
2024-10-06 20:05:49,606 - ERROR - 
2024-10-06 20:05:49,606 - ERROR - 

2024-10-06 20:15:14,473 - ERROR - Uncaught exception
Traceback (most recent call last):
  File "/home/frigiel/Documents/VSCODE/Kaboom/Server/server.py", line 44, in <module>
    accept()
  File "/home/frigiel/Documents/VSCODE/Kaboom/Server/server.py", line 29, in accept
    conn, address = server_socket.accept()
                    ^^^^^^^^^^^^^^^^^^^^^^
  File "/usr/lib/python3.12/socket.py", line 295, in accept
    fd, addr = self._accept()
               ^^^^^^^^^^^^^^
KeyboardInterrupt
2024-10-06 20:15:15,073 - ERROR - Exception ignored in: 
2024-10-06 20:15:15,073 - ERROR - <module 'threading' from '/usr/lib/python3.12/threading.py'>
2024-10-06 20:15:15,073 - ERROR - 

2024-10-06 20:15:15,073 - ERROR - Traceback (most recent call last):

2024-10-06 20:15:15,074 - ERROR -   File "/usr/lib/python3.12/threading.py", line 1624, in _shutdown

2024-10-06 20:15:15,075 - ERROR -     
2024-10-06 20:15:15,075 - ERROR - lock.acquire()
2024-10-06 20:15:15,075 - ERROR - 

2024-10-06 20:15:15,075 - ERROR - KeyboardInterrupt
2024-10-06 20:15:15,075 - ERROR - : 
2024-10-06 20:15:15,075 - ERROR - 
2024-10-06 20:15:15,075 - ERROR - 

